<mujoco model="digit">
       <compiler angle="radian" meshdir="meshes/" />

       <default>
              <default class='collision'>
                     <geom group="0" contype='1' conaffinity='1' condim='3' friction="0.7 0.3 0.3"
                            rgba="0 0 0 0" />
              </default>
              <default class="visual">
                     <geom group="1" type="mesh" contype="0" conaffinity="0" rgba="0.8 0.8 0.8 1" />
              </default>
              <light castshadow="false" />
              <joint damping="0.01" armature="0.01" type="hinge" pos="0 0 0" />
       </default>

       <asset>
              <mesh name="torso" file="torso.stl" />
              <mesh name="left-waist-cap" file="left-waist-cap.stl" scale="1 -1 1" />
              <mesh name="hip-yaw-housing" file="hip-yaw-housing.stl" />
              <mesh name="hip-pitch-housing" file="hip-pitch-housing.stl" />
              <mesh name="hip-pitch" file="hip-pitch.stl" />
              <mesh name="achilles-rod" file="achilles-rod.stl" />
              <mesh name="knee" file="knee.stl" />
              <mesh name="shin" file="shin.stl" />
              <mesh name="tarsus" file="tarsus.stl" />
              <mesh name="heel-spring" file="heel-spring.stl" />
              <mesh name="toe-output-ll" file="toe-output-ll.stl" />
              <mesh name="toe-A-rod" file="toe-A-rod.stl" />
              <mesh name="toe-output-lr" file="toe-output-lr.stl" />
              <mesh name="toe-B-rod" file="toe-B-rod.stl" />
              <mesh name="toe-pitch" file="toe-pitch.stl" />
              <mesh name="toe-roll" file="toe-roll.stl" />
              <mesh name="left-shoulder-cap" file="left-shoulder-cap.stl" />
              <mesh name="arm-L1" file="arm-L1.stl" />
              <mesh name="arm-L2" file="arm-L2.stl" />
              <mesh name="arm-L3" file="arm-L3.stl" />
              <mesh name="arm-L4" file="arm-L4.stl" />
              <mesh name="right-waist-cap" file="right-waist-cap.stl" />
              <mesh name="hip-yaw-housing1" file="hip-yaw-housing.stl" scale="1 -1 1" />
              <mesh name="hip-pitch-housing1" file="hip-pitch-housing.stl" scale="1 -1 1" />
              <mesh name="hip-pitch1" file="hip-pitch.stl" scale="1 -1 1" />
              <mesh name="achilles-rod1" file="achilles-rod.stl" scale="1 -1 1" />
              <mesh name="knee1" file="knee.stl" scale="1 -1 1" />
              <mesh name="shin1" file="shin.stl" scale="1 -1 1" />
              <mesh name="tarsus1" file="tarsus.stl" scale="1 -1 1" />
              <mesh name="heel-spring1" file="heel-spring.stl" scale="1 -1 1" />
              <mesh name="toe-output-rl" file="toe-output-rl.stl" scale="1 -1 1" />
              <mesh name="toe-A-rod1" file="toe-A-rod.stl" scale="1 -1 1" />
              <mesh name="toe-output-rr" file="toe-output-rr.stl" scale="1 -1 1" />
              <mesh name="toe-B-rod1" file="toe-B-rod.stl" scale="1 -1 1" />
              <mesh name="toe-pitch1" file="toe-pitch.stl" scale="1 -1 1" />
              <mesh name="toe-roll1" file="toe-roll.stl" scale="1 -1 1" />
              <mesh name="right-shoulder-cap" file="right-shoulder-cap.stl" scale="1 -1 1" />
              <mesh name="arm-L11" file="arm-L1.stl" scale="1 -1 1" />
              <mesh name="arm-L21" file="arm-L2.stl" scale="1 -1 1" />
              <mesh name="arm-L31" file="arm-L3.stl" scale="1 -1 1" />
              <mesh name="arm-L41" file="arm-L4.stl" scale="1 -1 1" />

              <texture type="skybox" builtin="gradient" width="512" height="512" rgb1=".4 .6 .8"
                     rgb2="0 0 0" />
              <texture name="texgeom" type="cube" builtin="flat" mark="cross" width="128"
                     height="128"
                     rgb1="0.6 0.6 0.6" rgb2="0.6 0.6 0.6" markrgb="1 1 1" />
              <texture name="texplane" type="2d" builtin="checker" rgb1=".4 .4 .4" rgb2=".6 .6 .6"
                     width="512" height="512" />
              <material name='MatPlane' reflectance='0.3' texture="texplane" texrepeat="1 1"
                     texuniform="true"
                     rgba=".7 .7 .7 1" />

       </asset>

       <option collision="all" timestep="0.001" tolerance="1e-20" solver="Newton" integrator="RK4"
              gravity="0 0 -9.806" iterations="50" cone="elliptic" />

       <worldbody>
              <light directional="true" diffuse=".8 .8 .8" pos="0 0 10" dir="0 0 -10" />
              <geom name="floor" pos="0 0 0" type="plane" size="0 0 1" material="MatPlane" />
              <camera name="track" mode="targetbody" target="torso" pos="2.5 -2.3 1.2"
                     xyaxes="1 0 0 0 0.707 0.707" />

              <body name="torso" pos="0 0 1">
                     <inertial pos="-0.00148645 0.000175054 0.252154"
                            quat="0.999974 8.03746e-05 -0.00708699 -0.000904934" mass="17.17"
                            diaginertia="0.492749 0.439332 0.127268" />

                     <joint type="free" limited='false' damping="0" stiffness="0" armature="0" />
                     <geom type='ellipsoid' size='0.12 0.12 0.06' pos='0.02 0 0.58' euler='0 0 0'
                            rgba="0.8 0.8 0.8 1" />

                     <geom class="visual" mesh="torso" />
                     <geom class="visual" pos="-0.001 0.09 0"
                            quat="0.000281544 -0.707107 -0.000281544 0.707107" type="mesh"
                            contype="0" conaffinity="0" group="1" mesh="left-waist-cap" />
                     <geom class="visual" pos="0.001 0.12 0.4"
                            quat="0.704416 -0.0616285 -0.704416 0.0616285" type="mesh" contype="0"
                            conaffinity="0" group="1" mesh="left-shoulder-cap" />
                     <geom class="visual" pos="-0.001 -0.09 0"
                            quat="0.000281544 0.707107 -0.000281544 -0.707107" type="mesh"
                            contype="0" conaffinity="0" group="1" mesh="right-waist-cap" />
                     <geom class="visual" pos="0.001 -0.12 0.4"
                            quat="0.704416 0.0616285 -0.704416 -0.0616285" type="mesh" contype="0"
                            conaffinity="0" group="1" mesh="right-shoulder-cap" />

                     <geom type='box' size='0.0975 0.087 0.245' pos='0.008 0 0.21' euler='0 0 0'
                            class='collision' />
                     <geom type='cylinder' size='0.05 0.0325' pos='0.02 0 0.49' euler='0 0 0'
                            class='collision' />

                     <site name='imu' pos='0 0 0' euler='0 -90 0' size='0.01' />


                     <body name="left_hip_roll" pos="-0.001 0.091 0"
                            quat="0.694697 0.131892 -0.694697 -0.131892">
                            <inertial pos="-0.001967 0.000244 0.031435"
                                   quat="0.698229 -0.0219238 -0.0143848 0.715394" mass="0.915088"
                                   diaginertia="0.00114812 0.00101759 0.00076529" />
                            <joint name="left_hip_roll_joint" pos="0 0 0" axis="0 0 1"
                                   limited="true" range="-1.0472 1.0472" damping='1.000000'
                                   frictionloss='1.000000' armature='0.1728' />
                            <geom class="visual" mesh="hip-yaw-housing" />
                            <body name="left_hip_yaw" pos="-0.0505 0 0.044"
                                   quat="0.707107 0 -0.707107 0">
                                   <inertial pos="1e-05 -0.001945 0.042033"
                                          quat="0.705887 0.0152563 -0.0169853 0.707957"
                                          mass="0.818753"
                                          diaginertia="0.00193142 0.001627 0.000767577" />
                                   <joint name="left_hip_yaw_joint" pos="0 0 0" axis="0 0 1"
                                          limited="true" range="-0.698132 0.698132"
                                          damping='1.000000' frictionloss='1.000000'
                                          armature='0.0675' />
                                   <geom class="visual" mesh="hip-pitch-housing" />
                                   <body name="left_hip_pitch" pos="0 0.004 0.068"
                                          quat="0.270598 0.270598 -0.653281 0.653281">
                                          <inertial pos="0.060537 0.000521 -0.038857"
                                                 quat="0.0892178 0.703019 0.0953661 0.699078"
                                                 mass="6.24428"
                                                 diaginertia="0.0340064 0.033299 0.0115307" />
                                          <joint name="left_hip_pitch_joint" pos="0 0 0"
                                                 axis="0 0 -1" limited="true" range="-1.0472 1.5708"
                                                 damping='1.000000' frictionloss='0.500000'
                                                 armature='0.120576' />
                                          <geom class="visual" mesh="hip-pitch" />
                                          <geom type='cylinder' size='0.05 0.072' pos='0 0 -0.04'
                                                 euler='0 0 0' class='collision' />
                                          <geom type='cylinder' size='0.05 0.072' pos='0.12 0 -0.04'
                                                 euler='0 0 0' class='collision' />
                                          <geom type='box' size='0.06 0.05 0.072' pos='0.06 0 -0.04'
                                                 euler='0 0 0' class='collision' />
                                          <body name="left_achillies_rod" pos="0 0 0.046"
                                                 quat="0.752692 0.0265893 0.0238029 -0.657405">
                                                 <inertial pos="0.2506 0 0" quat="0.5 0.5 0.5 0.5"
                                                        mass="0.178148"
                                                        diaginertia="0.004501 0.004501 3e-06" />
                                                 <joint name="left_achillies_rod_joint" type="ball"
                                                        limited="false" damping="0.010000" />
                                                 <geom class="visual" mesh="achilles-rod" />
                                          </body>
                                          <body name="left_knee" pos="0.12 0 0.0045"
                                                 quat="0.707107 0 0 -0.707107">
                                                 <inertial pos="0.045641 0.042154 0.001657"
                                                        quat="-0.167216 0.690239 0.176024 0.681634"
                                                        mass="1.22708"
                                                        diaginertia="0.00702026 0.00607564 0.00166411" />
                                                 <joint name="left_knee_joint" pos="0 0 0"
                                                        axis="0 0 1" limited="true"
                                                        range="-1.2392 0.8727" damping="1.000000"
                                                        frictionloss="0.500000" armature="0.120576" />
                                                 <geom class="visual" mesh="knee" />
                                                 <body name="left_shin" pos="0.060677 0.047406 0">
                                                        <inertial pos="0.174265 0.010265 0.00107"
                                                               quat="0.0280548 0.710242 -0.00805869 0.703352"
                                                               mass="0.895793"
                                                               diaginertia="0.022795 0.0225481 0.00106995" />
                                                        <geom class="visual" mesh="shin" />
                                                        <geom type='cylinder' size='0.03 0.1715'
                                                               pos='0.23 0 0'
                                                               euler='0 1.5707963267 0'
                                                               class='collision' />
                                                        <geom type='cylinder' size='0.05 0.1'
                                                               pos='0.125 0.009 0'
                                                               euler='1.5707963267 1.4660765716752 0'
                                                               class='collision' />
                                                        <body name="left_tarsus"
                                                               pos="0.434759 0.02 0"
                                                               quat="0.622515 0 0 0.782608">
                                                               <inertial
                                                                      pos="0.100777 -0.029183 0.000678"
                                                                      quat="0.0775034 0.707626 0.0502274 0.700526"
                                                                      mass="1.32286"
                                                                      diaginertia="0.016504 0.0164306 0.000907334" />
                                                               <joint name="left_tarsus_joint"
                                                                      pos="0 0 0" axis="0 0 1"
                                                                      limited="true"
                                                                      range="-0.8779 1.2497" />
                                                               <geom class="visual" mesh="tarsus" />
                                                               <body name="left_heel_spring"
                                                                      pos="-0.01766 -0.029456 0.00104"
                                                                      quat="0.209352 0.0109031 -0.0375468 0.977058">
                                                                      <inertial
                                                                             pos="0.049086 0.004739 -4.5e-05"
                                                                             quat="0.504912 0.505969 0.494741 0.494257"
                                                                             mass="0.230018"
                                                                             diaginertia="0.000740328 0.000701002 5.46701e-05" />
                                                                      <geom class="visual"
                                                                             mesh="heel-spring" />
                                                               </body>
                                                               <body name="left_toe_A"
                                                                      pos="0.059 -0.034 -0.0276"
                                                                      quat="-1.61254e-08 0.694909 -0.719097 1.66867e-08">
                                                                      <inertial
                                                                             pos="0.005161 1e-06 -0.002248"
                                                                             quat="0 0.675331 0 0.737515"
                                                                             mass="0.139557"
                                                                             diaginertia="7.43528e-05 5.8e-05 2.86472e-05" />
                                                                      <joint name="left_toe_A_joint"
                                                                             pos="0 0 0"
                                                                             axis="0 0 1"
                                                                             limited="true"
                                                                             range="-0.912807 1.26449"
                                                                             damping='1.000000'
                                                                             frictionloss='1.000000'
                                                                             armature='0.035' />
                                                                      <geom class="visual"
                                                                             mesh="toe-output-ll" />
                                                                      <body name="left_toe_A_rod"
                                                                             pos="0.057 0 -0.008"
                                                                             quat="0.697893 -0.0113021 0.0151583 -0.715953">
                                                                             <inertial
                                                                                    pos="0.171071 0 0"
                                                                                    quat="0.5 0.5 0.5 0.5"
                                                                                    mass="0.090983"
                                                                                    diaginertia="0.001182 0.001182 1e-06" />
                                                                             <joint
                                                                                    name="left_toe_A_rod_joint"
                                                                                    type="ball"
                                                                                    limited="false"
                                                                                    damping="0.010000" />
                                                                             <geom class="visual"
                                                                                    mesh="toe-A-rod" />
                                                                      </body>
                                                               </body>
                                                               <body name="left_toe_B"
                                                                      pos="0.111 -0.034 0.0276"
                                                                      quat="0.694918 0 0 -0.719089">
                                                                      <inertial
                                                                             pos="0.005161 1e-06 -0.002248"
                                                                             quat="0 0.675331 0 0.737515"
                                                                             mass="0.139557"
                                                                             diaginertia="7.43528e-05 5.8e-05 2.86472e-05" />
                                                                      <joint name="left_toe_B_joint"
                                                                             pos="0 0 0"
                                                                             axis="0 0 1"
                                                                             limited="true"
                                                                             range="-0.912807 1.26449"
                                                                             damping='1.000000'
                                                                             frictionloss='1.000000'
                                                                             armature='0.035' />
                                                                      <geom class="visual"
                                                                             mesh="toe-output-lr" />
                                                                      <body name="left_toe_B_rod"
                                                                             pos="0.057 0 -0.008"
                                                                             quat="0.69825 -0.0205714 -0.0173998 0.715347">
                                                                             <inertial
                                                                                    pos="0.142991 0 0"
                                                                                    quat="0.5 0.5 0.5 0.5"
                                                                                    mass="0.079507"
                                                                                    diaginertia="0.000768 0.000768 1e-06" />
                                                                             <joint
                                                                                    name="left_toe_B_rod_joint"
                                                                                    type="ball"
                                                                                    limited="false"
                                                                                    damping="0.010000" />
                                                                             <geom class="visual"
                                                                                    mesh="toe-B-rod" />
                                                                      </body>
                                                               </body>
                                                               <body name="left_toe_pitch"
                                                                      pos="0.408 -0.04 0"
                                                                      quat="0.826576 0 0 0.562825">
                                                                      <inertial
                                                                             pos="-0.000141 2e-06 3e-06"
                                                                             quat="0.707107 0 0 0.707107"
                                                                             mass="0.043881"
                                                                             diaginertia="8e-06 5e-06 5e-06" />
                                                                      <joint
                                                                             name="left_toe_pitch_joint"
                                                                             pos="0 0 0"
                                                                             axis="0 0 1"
                                                                             limited="true"
                                                                             range="-0.785398 0.785398" />
                                                                      <geom class="visual"
                                                                             mesh="toe-pitch" />
                                                                      <body name="left_toe_roll"
                                                                             pos="0 0 0"
                                                                             quat="0.707107 0 0.707107 0">
                                                                             <inertial
                                                                                    pos="9e-06 -0.028084 -0.023204"
                                                                                    quat="0.686347 0.170083 -0.170083 0.686347"
                                                                                    mass="0.531283"
                                                                                    diaginertia="0.00191487 0.00187 0.000544125" />
                                                                             <joint
                                                                                    name="left_toe_roll_joint"
                                                                                    pos="0 0 0"
                                                                                    axis="0 0 1"
                                                                                    limited="true"
                                                                                    range="-0.6109 0.6109" />
                                                                             <geom class="visual"
                                                                                    mesh="toe-roll" />
                                                                             <geom type='box'
                                                                                    size='0.04 0.1175 0.0115'
                                                                                    pos='0 -0.0437 -0.0255'
                                                                                    euler='-1.047197551 0 0'
                                                                                    class='collision' />
                                                                      </body>
                                                               </body>
                                                        </body>
                                                 </body>
                                          </body>
                                   </body>
                            </body>
                     </body>
                     <body name="left_shoulder_roll" pos="-0.001 0.12 0.4"
                            quat="0.704416 -0.0616285 -0.704416 0.0616285">
                            <inertial pos="9e-06 -0.003158 0.023405"
                                   quat="0.797183 0.0222446 -0.0335247 0.602396" mass="0.535396"
                                   diaginertia="0.0007569 0.000700085 0.000295016" />
                            <joint name="left_shoulder_roll_joint" pos="0 0 0" axis="0 0 1"
                                   limited="true" range="-1.309 1.309" damping='2.000000'
                                   frictionloss='2.000000' armature='0.1728' />
                            <geom class="visual" mesh="arm-L1" />
                            <body name="left_shoulder_pitch" pos="-0.00017 -0.011055 0.0555"
                                   quat="0.653281 0.653281 0.270598 -0.270598">
                                   <inertial pos="-4.2e-05 -0.061882 -0.073788"
                                          quat="0.544822 0.838549 0.00141069 -0.00163215"
                                          mass="1.44036"
                                          diaginertia="0.00676101 0.00668785 0.00117714" />
                                   <joint name="left_shoulder_pitch_joint" pos="0 0 0" axis="0 0 -1"
                                          limited="true" range="-2.5307 2.5307" damping='2.000000'
                                          frictionloss='2.000000' armature='0.1728' />
                                   <geom class="visual" mesh="arm-L2" />
                                   <geom type='cylinder' size='0.038 0.07' pos='0 -0.093 -0.1'
                                          euler='1.57079632 0 0' class='collision' />
                                   <body name="left_shoulder_yaw" pos="0 -0.165 -0.1"
                                          quat="0.707107 0.707107 0 0">
                                          <inertial pos="-3e-05 -0.001937 0.11407"
                                                 quat="0.716816 0.000904824 -0.000769054 0.697261"
                                                 mass="1.06539"
                                                 diaginertia="0.00700306 0.00696697 0.000672964" />
                                          <joint name="shoulder_yaw_joint_left" pos="0 0 0"
                                                 axis="0 0 1" limited="true" range="-1.7453 1.7453"
                                                 damping='1.000000' frictionloss='2.000000'
                                                 armature='0.0675' />
                                          <geom class="visual" mesh="arm-L3" />
                                          <geom type='cylinder' size='0.038 0.0675'
                                                 pos='0 0 0.092558' euler='0 0 0' class='collision' />
                                          <geom type='cylinder' size='0.03 0.04'
                                                 pos='0 -0.0035 0.185'
                                                 euler='1.57079632 0 0.392699081' class='collision' />
                                          <body name="left_elbow" pos="0 -0.0385 0.185"
                                                 quat="0.69352 0.69352 -0.13795 0.13795">
                                                 <inertial pos="0.107996 -0.000521 -0.017765"
                                                        quat="0.0155295 0.758388 0.0205611 0.651294"
                                                        mass="0.550582"
                                                        diaginertia="0.00965176 0.00956386 0.000261375" />
                                                 <joint name="left_elbow_joint" pos="0 0 0"
                                                        axis="0 0 1" limited="true"
                                                        range="-1.3526 1.3526" damping='1.000000'
                                                        frictionloss='2.000000' armature='0.1728' />
                                                 <geom class="visual" mesh="arm-L4" />
                                                 <geom type='cylinder' size='0.013 0.1565'
                                                        pos='0.184 0.01 -0.026'
                                                        euler='-3.316125578789 1.36135682 -3.1415926'
                                                        class='collision' />
                                                 <geom type='sphere' size='0.015'
                                                        pos='0.37937 0 -0.061912' euler='0 0 0'
                                                        class='collision' />
                                                 <site name='left_hand' pos='0.369 0 -0.07912'
                                                        euler='1.57079632 0 -0.1745329252'
                                                        size='0.01' />
                                          </body>
                                   </body>
                            </body>
                     </body>

                     <body name="right_hip_roll" pos="-0.001 -0.091 0"
                            quat="0.694697 -0.131892 -0.694697 0.131892">
                            <inertial pos="-0.001967 -0.000244 0.031435"
                                   quat="0.715394 -0.0143848 -0.0219238 0.698229" mass="0.915088"
                                   diaginertia="0.00114812 0.00101759 0.00076529" />
                            <joint name="right_hip_roll_joint" pos="0 0 0" axis="0 0 1"
                                   limited="true" range="-1.0472 1.0472" damping='1.000000'
                                   frictionloss='1.000000' armature='0.1728' />
                            <geom class="visual" mesh="hip-yaw-housing1" />
                            <body name="right_hip_yaw" pos="-0.0505 0 0.044"
                                   quat="0.707107 0 -0.707107 0">
                                   <inertial pos="1e-05 0.001945 0.042033"
                                          quat="0.707957 -0.0169853 0.0152563 0.705887"
                                          mass="0.818753"
                                          diaginertia="0.00193142 0.001627 0.000767577" />
                                   <joint name="right_hip_yaw_joint" pos="0 0 0" axis="0 0 1"
                                          limited="true" range="-0.698132 0.698132"
                                          damping='1.000000' frictionloss='1.000000'
                                          armature='0.0675' />
                                   <geom class="visual" mesh="hip-pitch-housing1" />
                                   <body name="right_hip_pitch" pos="0 -0.004 0.068"
                                          quat="0.270598 -0.270598 -0.653281 -0.653281">
                                          <inertial pos="0.060537 -0.000521 -0.038857"
                                                 quat="-0.0892178 0.703019 -0.0953661 0.699078"
                                                 mass="6.24428"
                                                 diaginertia="0.0340064 0.033299 0.0115307" />
                                          <joint name="right_hip_pitch_joint" pos="0 0 0"
                                                 axis="0 0 -1" limited="true" range="-1.0472 1.5708"
                                                 damping='1.000000' frictionloss='0.500000'
                                                 armature='0.120576' />
                                          <geom class="visual" mesh="hip-pitch1" />
                                          <geom type='cylinder' size='0.05 0.072' pos='0 0 -0.04'
                                                 euler='0 0 0' class='collision' />
                                          <geom type='cylinder' size='0.05 0.072' pos='0.12 0 -0.04'
                                                 euler='0 0 0' class='collision' />
                                          <geom type='box' size='0.06 0.05 0.072' pos='0.06 0 -0.04'
                                                 euler='0 0 0' class='collision' />

                                          <body name="right_achillies_rod" pos="0 0 0.046"
                                                 quat="0.752692 -0.0265893 0.0238029 0.657405">
                                                 <inertial pos="0.2506 0 0" quat="0.5 0.5 0.5 0.5"
                                                        mass="0.178148"
                                                        diaginertia="0.004501 0.004501 3e-06" />
                                                 <joint name="right_achillies_rod_joint" type="ball"
                                                        limited="false" damping="0.010000" />
                                                 <geom class="visual" mesh="achilles-rod1" />
                                          </body>
                                          <body name="right_knee" pos="0.12 0 0.0045"
                                                 quat="0.707107 0 0 0.707107">
                                                 <inertial pos="0.045641 -0.042154 0.001657"
                                                        quat="0.167216 0.690239 -0.176024 0.681634"
                                                        mass="1.22708"
                                                        diaginertia="0.00702026 0.00607564 0.00166411" />
                                                 <joint name="right_knee_joint" pos="0 0 0"
                                                        axis="0 0 1" limited="true"
                                                        range="-0.8727 1.2392" damping='1.000000'
                                                        frictionloss='0.500000' armature='0.120576' />
                                                 <geom class="visual" mesh="knee1" />
                                                 <body name="right_shin" pos="0.060677 -0.047406 0">
                                                        <inertial pos="0.174265 -0.010265 0.00107"
                                                               quat="-0.0280548 0.710242 0.00805869 0.703352"
                                                               mass="0.895793"
                                                               diaginertia="0.022795 0.0225481 0.00106995" />
                                                        <geom class="visual" mesh="shin1" />
                                                        <geom type='cylinder' size='0.03 0.1715'
                                                               pos='0.23 0 0'
                                                               euler='0 1.5707963267 0'
                                                               class='collision' />
                                                        <geom type='cylinder' size='0.05 0.1'
                                                               pos='0.125 -0.009 0'
                                                               euler='-1.5707963267 1.4660765716752 0'
                                                               class='collision' />
                                                        <body name="right_tarsus"
                                                               pos="0.434759 -0.02 0"
                                                               quat="0.622515 0 0 -0.782608">
                                                               <inertial
                                                                      pos="0.100777 0.029183 0.000678"
                                                                      quat="-0.0775034 0.707626 -0.0502274 0.700526"
                                                                      mass="1.32286"
                                                                      diaginertia="0.016504 0.0164306 0.000907334" />
                                                               <joint name="right_tarsus_joint"
                                                                      pos="0 0 0" axis="0 0 1"
                                                                      limited="true"
                                                                      range="-1.2497 0.8779" />
                                                               <geom class="visual" mesh="tarsus1" />
                                                               <body name="right_heel_spring"
                                                                      pos="-0.01766 0.029456 0.00104"
                                                                      quat="0.209352 -0.0109031 -0.0375468 -0.977058">
                                                                      <inertial
                                                                             pos="0.049086 -0.004739 -4.5e-05"
                                                                             quat="0.494257 0.494741 0.505969 0.504912"
                                                                             mass="0.230018"
                                                                             diaginertia="0.000740328 0.000701002 5.46701e-05" />
                                                                      <geom class="visual"
                                                                             mesh="heel-spring1" />
                                                               </body>
                                                               <body name="right_toe_A"
                                                                      pos="0.059 0.034 -0.0276"
                                                                      quat="-1.61254e-08 -0.694909 -0.719097 -1.66867e-08">
                                                                      <inertial
                                                                             pos="0.005161 -1e-06 -0.002248"
                                                                             quat="0 0.675331 0 0.737515"
                                                                             mass="0.139557"
                                                                             diaginertia="7.43528e-05 5.8e-05 2.86472e-05" />
                                                                      <joint
                                                                             name="right_toe_A_joint"
                                                                             pos="0 0 0"
                                                                             axis="0 0 1"
                                                                             limited="true"
                                                                             range="-1.26449 0.912807"
                                                                             damping='1.000000'
                                                                             frictionloss='1.000000'
                                                                             armature='0.035' />
                                                                      <geom class="visual"
                                                                             mesh="toe-output-rl" />
                                                                      <body name="right_toe_A_rod"
                                                                             pos="0.057 0 -0.008"
                                                                             quat="0.697893 0.0113021 0.0151583 0.715953">
                                                                             <inertial
                                                                                    pos="0.171071 0 0"
                                                                                    quat="0.5 0.5 0.5 0.5"
                                                                                    mass="0.090983"
                                                                                    diaginertia="0.001182 0.001182 1e-06" />
                                                                             <joint
                                                                                    name="right_toe_A_rod_joint"
                                                                                    type="ball"
                                                                                    limited="false"
                                                                                    damping="0.010000" />
                                                                             <geom class="visual"
                                                                                    mesh="toe-A-rod1" />
                                                                      </body>
                                                               </body>
                                                               <body name="right_toe_B"
                                                                      pos="0.111 0.034 0.0276"
                                                                      quat="0.694918 0 0 0.719089">
                                                                      <inertial
                                                                             pos="0.005161 -1e-06 -0.002248"
                                                                             quat="0 0.675331 0 0.737515"
                                                                             mass="0.139557"
                                                                             diaginertia="7.43528e-05 5.8e-05 2.86472e-05" />
                                                                      <joint
                                                                             name="right_toe_B_joint"
                                                                             pos="0 0 0"
                                                                             axis="0 0 1"
                                                                             limited="true"
                                                                             range="-0.912807 1.26449"
                                                                             damping='1.000000'
                                                                             frictionloss='1.000000'
                                                                             armature='0.035' />
                                                                      <geom class="visual"
                                                                             mesh="toe-output-rr" />
                                                                      <body name="right_toe_B_rod"
                                                                             pos="0.057 0 -0.008"
                                                                             quat="0.69825 0.0205714 -0.0173998 -0.715347">
                                                                             <inertial
                                                                                    pos="0.142991 0 0"
                                                                                    quat="0.5 0.5 0.5 0.5"
                                                                                    mass="0.079507"
                                                                                    diaginertia="0.000768 0.000768 1e-06" />
                                                                             <joint
                                                                                    name="right_toe_B_rod_joint"
                                                                                    type="ball"
                                                                                    limited="false"
                                                                                    damping="0.010000" />
                                                                             <geom class="visual"
                                                                                    mesh="toe-B-rod1" />
                                                                      </body>
                                                               </body>
                                                               <body name="right_toe_pitch"
                                                                      pos="0.408 0.04 0"
                                                                      quat="0.826576 0 0 -0.562825">
                                                                      <inertial
                                                                             pos="-0.000141 -2e-06 3e-06"
                                                                             quat="0.707107 0 0 0.707107"
                                                                             mass="0.043881"
                                                                             diaginertia="8e-06 5e-06 5e-06" />
                                                                      <joint
                                                                             name="right_toe_pitch_joint"
                                                                             pos="0 0 0"
                                                                             axis="0 0 1"
                                                                             limited="true"
                                                                             range="-0.785398 0.785398" />
                                                                      <geom class="visual"
                                                                             mesh="toe-pitch1" />
                                                                      <body name="right_toe_roll"
                                                                             pos="0 0 0"
                                                                             quat="0.707107 0 0.707107 0">
                                                                             <inertial
                                                                                    pos="9e-06 0.028084 -0.023204"
                                                                                    quat="0.686347 -0.170083 0.170083 0.686347"
                                                                                    mass="0.531283"
                                                                                    diaginertia="0.00191487 0.00187 0.000544125" />
                                                                             <joint
                                                                                    name="right_toe_roll_joint"
                                                                                    pos="0 0 0"
                                                                                    axis="0 0 1"
                                                                                    limited="true"
                                                                                    range="-0.6109 0.6109" />
                                                                             <geom class="visual"
                                                                                    mesh="toe-roll1" />
                                                                             <geom type='box'
                                                                                    size='0.04 0.1175 0.0115'
                                                                                    pos='0 0.0437 -0.0255'
                                                                                    euler='1.047197551 0 0'
                                                                                    class='collision' />
                                                                      </body>
                                                               </body>
                                                        </body>
                                                 </body>
                                          </body>
                                   </body>
                            </body>
                     </body>
                     <body name="right_shoulder_roll" pos="-0.001 -0.12 0.4"
                            quat="0.704416 0.0616285 -0.704416 -0.0616285">
                            <inertial pos="9e-06 -0.003158 0.023405"
                                   quat="0.602396 -0.0335247 0.0222446 0.797183" mass="0.535396"
                                   diaginertia="0.0007569 0.000700085 0.000295016" />
                            <joint name="right_shoulder_roll_joint" pos="0 0 0" axis="0 0 1"
                                   limited="true" range="-1.309 1.309" damping='2.000000'
                                   frictionloss='2.000000' armature='0.1728' />
                            <geom class="visual" mesh="arm-L11" />
                            <body name="right_shoulder_pitch" pos="-0.00017 0.011055 0.0555"
                                   quat="0.653281 -0.653281 0.270598 0.270598">
                                   <inertial pos="-4.2e-05 0.061882 -0.073788"
                                          quat="0.838549 0.544822 0.00163215 -0.00141069"
                                          mass="1.44036"
                                          diaginertia="0.00676101 0.00668785 0.00117714" />
                                   <joint name="right_shoulder_pitch_joint" pos="0 0 0"
                                          axis="0 0 -1" limited="true" range="-2.5307 2.5307"
                                          damping='2.000000' frictionloss='2.000000'
                                          armature='0.1728' />
                                   <geom class="visual" mesh="arm-L21" />
                                   <geom type='cylinder' size='0.038 0.07' pos='0 0.093 -0.1'
                                          euler='-1.57079632 0 0' class='collision' />
                                   <body name="right_shoulder_yaw" pos="0 0.165 -0.1"
                                          quat="0.707107 -0.707107 0 0">
                                          <inertial pos="-3e-05 -0.001937 0.11407"
                                                 quat="0.697261 -0.000769054 0.000904824 0.716816"
                                                 mass="1.06539"
                                                 diaginertia="0.00700306 0.00696697 0.000672964" />
                                          <joint name="shoulder_yaw_joint_right" pos="0 0 0"
                                                 axis="0 0 1" limited="true" range="-1.7453 1.7453"
                                                 damping='1.000000' frictionloss='2.000000'
                                                 armature='0.0675' />
                                          <geom class="visual" mesh="arm-L31" />
                                          <geom type='cylinder' size='0.038 0.0675'
                                                 pos='0 0 0.092558' euler='0 0 0' class='collision' />
                                          <geom type='cylinder' size='0.03 0.04'
                                                 pos='0 -0.0035 0.185'
                                                 euler='1.57079633 0 0.3926991' class='collision' />
                                          <body name="right_elbow" pos="0 0.0385 0.185"
                                                 quat="0.69352 -0.69352 -0.13795 -0.13795">
                                                 <inertial pos="0.107996 0.000521 -0.017765"
                                                        quat="-0.0155295 0.758388 -0.0205611 0.651294"
                                                        mass="0.550582"
                                                        diaginertia="0.00965176 0.00956386 0.000261375" />
                                                 <joint name="right_elbow_joint" pos="0 0 0"
                                                        axis="0 0 1" limited="true"
                                                        range="-1.3526 1.3526" damping='1.000000'
                                                        frictionloss='2.000000' armature='0.1728' />
                                                 <geom class="visual" mesh="arm-L41" />
                                                 <geom type='cylinder' size='0.013 0.1565'
                                                        pos='0.184 0.01 -0.026'
                                                        euler='-3.316125578789 1.36135682 -3.1415926'
                                                        class='collision' />
                                                 <geom type='sphere' size='0.015'
                                                        pos='0.37937 0 -0.061912' euler='0 0 0'
                                                        class='collision' />
                                                 <site name='right_hand' pos='0.369 0 -0.07912'
                                                        euler='-1.57079633 0 0.1745329252'
                                                        size='0.01' />
                                          </body>
                                   </body>
                            </body>
                     </body>
              </body>
       </worldbody>


       <equality>
              <connect name='left_toe_A_rod' body1='left_toe_roll' body2='left_toe_A_rod'
                     anchor='0.0179 -0.009551 -0.054164' />
              <connect name='left_toe_B_rod' body1='left_toe_roll' body2='left_toe_B_rod'
                     anchor='-0.0181 -0.009551 -0.054164' />
              <connect name='left_achillies_rod' body1='left_heel_spring' body2='left_achillies_rod'
                     anchor='0.113789 -0.011056 0' />
              <connect name='right_toe_A_rod' body1='right_toe_roll' body2='right_toe_A_rod'
                     anchor='0.0179 0.009551 -0.054164' />
              <connect name='right_toe_B_rod' body1='right_toe_roll' body2='right_toe_B_rod'
                     anchor='-0.0181 0.009551 -0.054164' />
              <connect name='right_achillies_rod' body1='right_heel_spring'
                     body2='right_achillies_rod' anchor='0.113789 0.011056 0' />
       </equality>

       <actuator>
              <motor name='left_hip_roll_joint' joint='left_hip_roll_joint' />
              <motor name='left_hip_yaw_joint' joint='left_hip_yaw_joint' />
              <motor name='left_hip_pitch_joint' joint='left_hip_pitch_joint' />
              <motor name='left_knee_joint' joint='left_knee_joint' />
              <motor name="left_tarsus_joint" joint="left_tarsus_joint" />
              <motor name='left_toe_A_joint' joint='left_toe_A_joint' />
              <motor name='left_toe_B_joint' joint='left_toe_B_joint' />
              <motor name="toe_pitch_joint_left" joint="left_toe_pitch_joint" />
              <motor name="toe_roll_joint_left" joint="left_toe_roll_joint" />

              <motor name='left_shoulder_roll_joint' joint='left_shoulder_roll_joint' />
              <motor name='left_shoulder_pitch_joint' joint='left_shoulder_pitch_joint' />
              <motor name='left_shoulder_yaw_joint' joint='shoulder_yaw_joint_left' />
              <motor name='left_elbow_joint' joint='left_elbow_joint' />

              <motor name='right_hip_roll_joint' joint='right_hip_roll_joint' />
              <motor name='right_hip_yaw_joint' joint='right_hip_yaw_joint' />
              <motor name='right_hip_pitch_joint' joint='right_hip_pitch_joint' />
              <motor name='right_knee_joint' joint='right_knee_joint' />
              <motor name="right_tarsus_joint" joint="right_tarsus_joint" />
              <motor name='right_toe_A_joint' joint='right_toe_A_joint' />
              <motor name='right_toe_B_joint' joint='right_toe_B_joint' />
              <motor name="toe_pitch_joint_right" joint="right_toe_pitch_joint" />
              <motor name="toe_roll_joint_right" joint="right_toe_roll_joint" />


              <motor name='right_shoulder_roll_joint' joint='right_shoulder_roll_joint' />
              <motor name='right_shoulder_pitch_joint' joint='right_shoulder_pitch_joint' />
              <motor name='right_shoulder_yaw_joint' joint='shoulder_yaw_joint_right' />
              <motor name='right_elbow_joint' joint='right_elbow_joint' />
       </actuator>

       <sensor>
              <framequat name="Body_Quat" objtype="site" objname="imu" />
              <gyro name="Body_Gyro" site="imu" />
              <accelerometer name="Body_Acc" site="imu" />

              <jointpos name='left_hip_roll_joint_pos' joint='left_hip_roll_joint' />
              <jointpos name='left_hip_yaw_joint_pos' joint='left_hip_yaw_joint' />
              <jointpos name='left_hip_pitch_joint_pos' joint='left_hip_pitch_joint' />
              <jointpos name='left_knee_joint_pos' joint='left_knee_joint' />
              <jointpos name='left_tarsus_joint_pos' joint='left_tarsus_joint' />
              <jointpos name='left_toe_A_joint_pos' joint='left_toe_A_joint' />
              <jointpos name='left_toe_B_joint_pos' joint='left_toe_B_joint' />
              <jointpos name='left_toe_pitch_joint_pos' joint='left_toe_pitch_joint' />
              <jointpos name='left_toe_roll_joint_pos' joint='left_toe_roll_joint' />

              <jointpos name='left_shoulder_roll_joint_pos' joint='left_shoulder_roll_joint' />
              <jointpos name='left_shoulder_pitch_joint_pos' joint='left_shoulder_pitch_joint' />
              <jointpos name='shoulder_yaw_joint_left_pos' joint='shoulder_yaw_joint_left' />
              <jointpos name='left_elbow_joint_pos' joint='left_elbow_joint' />

              <jointpos name='right_hip_roll_joint_pos' joint='right_hip_roll_joint' />
              <jointpos name='right_hip_yaw_joint_pos' joint='right_hip_yaw_joint' />
              <jointpos name='right_hip_pitch_joint_pos' joint='right_hip_pitch_joint' />
              <jointpos name='right_knee_joint_pos' joint='right_knee_joint' />
              <jointpos name='right_tarsus_joint_pos' joint='right_tarsus_joint' />
              <jointpos name='right_toe_A_joint_pos' joint='right_toe_A_joint' />
              <jointpos name='right_toe_B_joint_pos' joint='right_toe_B_joint' />
              <jointpos name='right_toe_pitch_joint_pos' joint='right_toe_pitch_joint' />
              <jointpos name='right_toe_roll_joint_pos' joint='right_toe_roll_joint' />

              <jointpos name='right_shoulder_roll_joint_pos' joint='right_shoulder_roll_joint' />
              <jointpos name='right_shoulder_pitch_joint_pos' joint='right_shoulder_pitch_joint' />
              <jointpos name='shoulder_yaw_joint_right_pos' joint='shoulder_yaw_joint_right' />
              <jointpos name='right_elbow_joint_pos' joint='right_elbow_joint' />

              <jointvel name='left_hip_roll_joint_vel' joint='left_hip_roll_joint' />
              <jointvel name='left_hip_yaw_joint_vel' joint='left_hip_yaw_joint' />
              <jointvel name='left_hip_pitch_joint_vel' joint='left_hip_pitch_joint' />
              <jointvel name='left_knee_joint_vel' joint='left_knee_joint' />
              <jointvel name='left_tarsus_joint_vel' joint='left_tarsus_joint' />
              <jointvel name='left_toe_A_joint_vel' joint='left_toe_A_joint' />
              <jointvel name='left_toe_B_joint_vel' joint='left_toe_B_joint' />
              <jointvel name='left_toe_pitch_joint_vel' joint='left_toe_pitch_joint' />
              <jointvel name='left_toe_roll_joint_vel' joint='left_toe_roll_joint' />

              <jointvel name='left_shoulder_roll_joint_vel' joint='left_shoulder_roll_joint' />
              <jointvel name='left_shoulder_pitch_joint_vel' joint='left_shoulder_pitch_joint' />
              <jointvel name='shoulder_yaw_joint_left_vel' joint='shoulder_yaw_joint_left' />
              <jointvel name='left_elbow_joint_vel' joint='left_elbow_joint' />

              <jointvel name='right_hip_roll_joint_vel' joint='right_hip_roll_joint' />
              <jointvel name='right_hip_yaw_joint_vel' joint='right_hip_yaw_joint' />
              <jointvel name='right_hip_pitch_joint_vel' joint='right_hip_pitch_joint' />
              <jointvel name='right_knee_joint_vel' joint='right_knee_joint' />

              <jointvel name='right_tarsus_joint' joint='right_tarsus_joint' />
              <jointvel name='right_toe_A_joint_vel' joint='right_toe_A_joint' />
              <jointvel name='right_toe_B_joint_vel' joint='right_toe_B_joint' />
              <jointvel name='right_toe_pitch_joint_vel' joint='right_toe_pitch_joint' />
              <jointvel name='right_toe_roll_joint_vel' joint='right_toe_roll_joint' />

              <jointvel name='right_shoulder_roll_joint_vel' joint='right_shoulder_roll_joint' />
              <jointvel name='right_shoulder_pitch_joint_vel' joint='right_shoulder_pitch_joint' />
              <jointvel name='shoulder_yaw_joint_right_vel' joint='shoulder_yaw_joint_right' />
              <jointvel name='right_elbow_joint_vel' joint='right_elbow_joint' />
       </sensor>

</mujoco>